try~catch~finally
	try: 에러발생할 경우 바로 catch로 이동
	catch : 에러 발생 시 실행되는 코드
	finally : 에러 발생 유무와 상관없이 무조건 실행되는 코드(옵션)
	
	

1) 발생시킬 때 -> 던진다고 한다.(throw)
2) 명시적으로 인지할 때 -> 잡는다고 한다. (catch)



```js
console.log('Hello');
throw new Error('큰 문제가 생겼습니다!');
console.log('Code factory');    // 실행 안됨
```
```
Hello
d:\fruiedem\js\16_try_catch.js:2
throw new Error('큰 문제가 생겼습니다!');
^

Error: 큰 문제가 생겼습니다!
    at Object.<anonymous> (d:\fruiedem\js\16_try_catch.js:2:7)
    at Module._compile (node:internal/modules/cjs/loader:1256:14)
    at Module._extensions..js (node:internal/modules/cjs/loader:1310:10)
    at Module.load (node:internal/modules/cjs/loader:1119:32)
    at Module._load (node:internal/modules/cjs/loader:960:12)
    at Function.executeUserEntryPoint [as runMain] (node:internal/modules/run_main:81:12)
    at node:internal/main/run_main_module:23:47
```




```js
try {
    console.log('Hello');
    throw new Error('큰 문제가 생겼습니다!');
    console.log('Code factory');    // 실행 안됨
}catch(e){
    console.log('--- catch ---');
    console.log(e);
}finally{
    console.log('--- finally ---')
}
```
```
Hello
--- catch ---
Error: 큰 문제가 생겼습니다!
    at Object.<anonymous> (d:\fruiedem\js\16_try_catch.js:4:11)
    at Module._compile (node:internal/modules/cjs/loader:1256:14)
    at Module._extensions..js (node:internal/modules/cjs/loader:1310:10)
    at Module.load (node:internal/modules/cjs/loader:1119:32)
    at Module._load (node:internal/modules/cjs/loader:960:12)
    at Function.executeUserEntryPoint [as runMain] (node:internal/modules/run_main:81:12)
    at node:internal/main/run_main_module:23:47
--- finally ---
```